Workbook

Sheet Iteration_table
A1: MAHZOR_ID | B1: mushroom_type | C1: Iteration_ID | D1: Start_date | E1: Room_number | F1: Substrate
A2: 1 | B2: 1 | C2: 24 | D2: 45460 | E2: 4 | F2: 160
A3: 2 | B3: 1 | C3: 23 | D3: 45447 | E3: 5 | F3: 237.5
A4: 3 | B4: 1 | C4: 22 | D4: 45435 | E4: 4 | F4: 240
A5: 4 | B5: 1 | C5: 21 | D5: 45423 | E5: 5 | F5: 240
A6: 5 | B6: 1 | C6: 20 | D6: 45412 | E6: 4 | F6: 160
A7: 6 | B7: 1 | C7: 19 | D7: 45406 | E7: 5 | F7: =32*2.5 -> 80
A8: 7 | B8: 1 | C8: 18 | D8: 45398 | E8: 5 | F8: =96*2.5 -> 240
A9: 8 | B9: 1 | C9: 17 | D9: 45381 | E9: 3 | F9: =96*2.5 -> 240
A10: 9 | B10: 1 | C10: 16 | D10: 45369 | E10: 4 | F10: =96*2.5 -> 240
A11: 10 | B11: 1 | C11: 15 | D11: 45348 | E11: 5 | F11: =96*2.5 -> 240
A12: 11 | B12: 1 | C12: 14 | D12: 45343 | E12: 3 | F12: =96*2.5 -> 240
A13: 12 | B13: 1 | C13: 13 | D13: 45337 | E13: 3 | F13: =95*2.5 -> 237.5
A14: 13 | B14: 1 | C14: 12 | D14: 45323 | E14: 4 | F14: =96*2.5 -> 240
A15: 14 | B15: 1 | C15: 11 | D15: 45316 | E15: 3 | F15: =96*2.5 -> 240
A16: 15 | B16: 1 | C16: 10 | D16: 45307 | E16: 3 | F16: 240
A17: 16 | B17: 1 | C17: 9 | D17: 45297 | E17: 5 | F17: 240
A18: 17 | B18: 1 | C18: 8 | D18: 45288 | E18: 4 | F18: 237.5
A19: 18 | B19: 1 | C19: 7 | D19: 45274 | E19: 4 | F19: 240
A20: 19 | B20: 1 | C20: 6 | D20: 45268 | E20: 3 | F20: 240
A21: 20 | B21: 1 | C21: 5 | D21: 45260 | E21: 5 | F21: 240
A22: 21 | B22: 1 | C22: 4 | D22: 45253 | E22: 4 | F22: 240

Sheet LOGS
A1: Log_id | B1: Mahzor_id | C1: Days_after_plant | D1: Date | E1: Hour | F1: AIR_temp | G1: Substrate_temp | H1: RH_Humadity | I1: CO2 | J1: day_hours | K1: Katif | L1: if_bagged
A2: 1 | B2: 1 | C2: 0 | D2: =VLOOKUP(B2, Iteration_table!$A$2:$D$1000, 4, FALSE) + C2 -> 45460 | E2: 0.66666667 | F2: 17.3 | G2: 1.2 | H2: 0.66 | I2: 512 | J2: 8 | K2: 0 | L2: TRUE
A3: 2 | B3: 1 | C3: 2 | D3: =VLOOKUP(B3, Iteration_table!$A$2:$D$1000, 4, FALSE) + C3 -> 45462 | E3: 0.58333333 | F3: 15.6 | G3: 14.6 | H3: 0.78 | I3: 772 | J3: 8 | K3: 0 | L3: TRUE
A4: 3 | B4: 1 | C4: 7 | D4: =VLOOKUP(B4, Iteration_table!$A$2:$D$1000, 4, FALSE) + C4 -> 45467 | E4: 0.75 | F4: 16 | G4: 15.7 | H4: 0.8 | I4: 1100 | J4: 8 | K4: 0 | L4: TRUE
A5: 4 | B5: 1 | C5: 9 | D5: =VLOOKUP(B5, Iteration_table!$A$2:$D$1000, 4, FALSE) + C5 -> 45469 | E5: 0.3125 | F5: 14.2 | G5: 15.7 | H5: 0.795 | I5: 745 | J5: 8 | K5: 0 | L5: TRUE
A6: 5 | B6: 1 | C6: 12 | D6: =VLOOKUP(B6, Iteration_table!$A$2:$D$1000, 4, FALSE) + C6 -> 45472 | L6: FALSE
A7: 6 | B7: 1 | C7: 20 | D7: =VLOOKUP(B7, Iteration_table!$A$2:$D$1000, 4, FALSE) + C7 -> 45480 | K7: 25 | L7: FALSE
A8: 7 | B8: 1 | C8: 21 | D8: =VLOOKUP(B8, Iteration_table!$A$2:$D$1000, 4, FALSE) + C8 -> 45481 | K8: 12.3 | L8: FALSE
A9: 8 | B9: 2 | C9: 1 | D9: =VLOOKUP(B9, Iteration_table!$A$2:$D$1000, 4, FALSE) + C9 -> 45448 | E9: 0.5 | F9: 15.5 | G9: 14.4 | H9: 0.85 | I9: 557 | J9: 8 | K9: 0 | L9: TRUE
A10: 9 | B10: 2 | C10: 12 | D10: =VLOOKUP(B10, Iteration_table!$A$2:$D$1000, 4, FALSE) + C10 -> 45459 | L10: FALSE
A11: 10 | B11: 2 | C11: 15 | D11: =VLOOKUP(B11, Iteration_table!$A$2:$D$1000, 4, FALSE) + C11 -> 45462 | E11: 0.58333333 | F11: 15.6 | G11: 15.4 | H11: 0.782 | I11: 860 | J11: 8 | K11: 0 | L11: FALSE
A12: 11 | B12: 2 | C12: 20 | D12: =VLOOKUP(B12, Iteration_table!$A$2:$D$1000, 4, FALSE) + C12 -> 45467 | E12: 0.75 | F12: 13.8 | G12: 14.4 | H12: 0.835 | I12: 765 | J12: 8 | L12: FALSE
A13: 12 | B13: 2 | C13: 22 | D13: =VLOOKUP(B13, Iteration_table!$A$2:$D$1000, 4, FALSE) + C13 -> 45469 | E13: 0.72916667 | F13: 13.8 | G13: 13.1 | H13: 0.8 | I13: 682 | J13: 8 | K13: 34.445 | L13: FALSE
A14: 13 | B14: 2 | C14: 25 | D14: =VLOOKUP(B14, Iteration_table!$A$2:$D$1000, 4, FALSE) + C14 -> 45472 | K14: 19 | L14: FALSE
A15: 14 | B15: 3 | C15: 1 | D15: =VLOOKUP(B15, Iteration_table!$A$2:$D$1000, 4, FALSE) + C15 -> 45436 | E15: 0.66666667 | F15: 15.4 | G15: 14.1 | H15: 0.82 | I15: 498 | J15: 8
A16: 15 | B16: 3 | C16: 3 | D16: =VLOOKUP(B16, Iteration_table!$A$2:$D$1000, 4, FALSE) + C16 -> 45438 | E16: 0.75 | F16: 16.4 | G16: 14.3 | H16: 0.71 | I16: 483 | J16: 8
A17: 16 | B17: 3 | C17: 4 | D17: =VLOOKUP(B17, Iteration_table!$A$2:$D$1000, 4, FALSE) + C17 -> 45439 | E17: 0.625 | F17: 15.3 | G17: 14.4 | H17: 0.84 | I17: 536 | J17: 8
A18: 17 | B18: 3 | C18: 5 | D18: =VLOOKUP(B18, Iteration_table!$A$2:$D$1000, 4, FALSE) + C18 -> 45440 | E18: 0.70833333 | F18: 14.5 | G18: 14.6 | H18: 0.93 | I18: 576 | J18: 8
A19: 18 | B19: 3 | C19: 6 | D19: =VLOOKUP(B19, Iteration_table!$A$2:$D$1000, 4, FALSE) + C19 -> 45441 | E19: 0.70833333 | F19: 14.6 | G19: 14.5 | H19: 0.85 | I19: 679 | J19: 8
A20: 19 | B20: 3 | C20: 8 | D20: =VLOOKUP(B20, Iteration_table!$A$2:$D$1000, 4, FALSE) + C20 -> 45443 | E20: 0.58333333 | F20: 14.6 | G20: 14.6 | H20: 0.87 | I20: 745 | J20: 8
A21: 20 | B21: 3 | C21: 10 | D21: =VLOOKUP(B21, Iteration_table!$A$2:$D$1000, 4, FALSE) + C21 -> 45445 | E21: 0.70833333 | F21: 13.9 | G21: 14.5 | H21: 0.83 | I21: 972 | J21: 8
A22: 21 | B22: 3 | C22: 11 | D22: =VLOOKUP(B22, Iteration_table!$A$2:$D$1000, 4, FALSE) + C22 -> 45446 | E22: 0.64583333 | F22: 15.3 | G22: 15.2 | H22: 0.84 | I22: 880 | J22: 8
A23: 22 | B23: 3 | C23: 13 | D23: =VLOOKUP(B23, Iteration_table!$A$2:$D$1000, 4, FALSE) + C23 -> 45448 | E23: 0.5 | F23: 16 | G23: 16.4 | H23: 0.78 | I23: 1185 | J23: 8
A24: 23 | B24: 3 | C24: 21 | D24: =VLOOKUP(B24, Iteration_table!$A$2:$D$1000, 4, FALSE) + C24 -> 45456 | K24: 44.5
A25: 24 | B25: 3 | C25: 24 | D25: =VLOOKUP(B25, Iteration_table!$A$2:$D$1000, 4, FALSE) + C25 -> 45459 | K25: 21.2
A26: 25 | B26: 3 | C26: 25 | D26: =VLOOKUP(B26, Iteration_table!$A$2:$D$1000, 4, FALSE) + C26 -> 45460 | K26: 19
A27: 26 | B27: 4 | C27: 0 | D27: =VLOOKUP(B27, Iteration_table!$A$2:$D$1000, 4, FALSE) + C27 -> 45423 | E27: 0.75 | F27: 13.7 | H27: 0.86 | I27: 556 | J27: 8 | L27: TRUE
A28: 27 | B28: 4 | C28: 1 | D28: =VLOOKUP(B28, Iteration_table!$A$2:$D$1000, 4, FALSE) + C28 -> 45424 | E28: 0.66666667 | F28: 15.3 | G28: 13.7 | H28: 0.78 | I28: 493 | J28: 8 | L28: TRUE
A29: 28 | B29: 4 | C29: 2 | D29: =VLOOKUP(B29, Iteration_table!$A$2:$D$1000, 4, FALSE) + C29 -> 45425 | E29: 0.5 | F29: 15.8 | G29: 13.4 | H29: 0.78 | I29: 474 | J29: 8 | L29: TRUE
A30: 29 | B30: 4 | C30: 5 | D30: =VLOOKUP(B30, Iteration_table!$A$2:$D$1000, 4, FALSE) + C30 -> 45428 | E30: 0.625 | F30: 15.9 | G30: 13.9 | H30: 0.79 | I30: 512 | J30: 8 | L30: TRUE
A31: 30 | B31: 4 | C31: 6 | D31: =VLOOKUP(B31, Iteration_table!$A$2:$D$1000, 4, FALSE) + C31 -> 45429 | E31: 0.45833333 | F31: 15.6 | G31: 14.1 | H31: 0.78 | I31: 540 | J31: 8 | L31: TRUE
A32: 31 | B32: 4 | C32: 8 | D32: =VLOOKUP(B32, Iteration_table!$A$2:$D$1000, 4, FALSE) + C32 -> 45431 | E32: 0.375 | F32: 15.2 | G32: 14.4 | H32: 0.84 | I32: 603 | J32: 8 | L32: TRUE
A33: 32 | B33: 4 | C33: 11 | D33: =VLOOKUP(B33, Iteration_table!$A$2:$D$1000, 4, FALSE) + C33 -> 45434 | E33: 0.5 | F33: 15.8 | G33: 15.4 | H33: 0.69 | I33: 479 | J33: 8 | L33: TRUE
A34: 33 | B34: 4 | C34: 12 | D34: =VLOOKUP(B34, Iteration_table!$A$2:$D$1000, 4, FALSE) + C34 -> 45435 | E34: 0.70833333 | F34: 16.1 | G34: 15.3 | H34: 0.76 | I34: 653 | J34: 8 | L34: TRUE
A35: 34 | B35: 4 | C35: 13 | D35: =VLOOKUP(B35, Iteration_table!$A$2:$D$1000, 4, FALSE) + C35 -> 45436 | E35: 0.6875 | F35: 16.5 | G35: 15.8 | H35: 0.71 | I35: 655 | J35: 8 | L35: TRUE
A36: 35 | B36: 4 | C36: 15 | D36: =VLOOKUP(B36, Iteration_table!$A$2:$D$1000, 4, FALSE) + C36 -> 45438 | E36: 0.58333333 | F36: 16.4 | G36: 15.3 | H36: 0.79 | I36: 809 | J36: 8 | L36: FALSE
A37: 36 | B37: 4 | C37: 16 | D37: =VLOOKUP(B37, Iteration_table!$A$2:$D$1000, 4, FALSE) + C37 -> 45439 | E37: 0.625 | F37: 16.5 | G37: 14.6 | H37: 0.72 | I37: 567 | J37: 8 | L37: FALSE
A38: 37 | B38: 4 | C38: 17 | D38: =VLOOKUP(B38, Iteration_table!$A$2:$D$1000, 4, FALSE) + C38 -> 45440 | E38: 0.70833333 | F38: 16 | G38: 14.9 | H38: 0.87 | I38: 690 | J38: 8 | L38: FALSE
A39: 38 | B39: 4 | C39: 18 | D39: =VLOOKUP(B39, Iteration_table!$A$2:$D$1000, 4, FALSE) + C39 -> 45441 | E39: 0.70833333 | F39: 15.6 | G39: 15.4 | H39: 0.84 | I39: 621 | J39: 8 | L39: FALSE
A40: 39 | B40: 4 | C40: 19 | D40: =VLOOKUP(B40, Iteration_table!$A$2:$D$1000, 4, FALSE) + C40 -> 45442 | J40: 8 | K40: 13.6 | L40: FALSE
...

Sheet Index
A1: mushroom_type | B1: 1 | C1: eryngii
B2: 2 | C2: Shitake
B3: 3 | C3: maitake
B4: 4 | C4: hericium
B5: 5 | C5: tiger swagill
B6: 6 | C6: nebrodensis
